<?xml version="1.0"?>
<robot name="simple_pendulum">

  <!-- Base Link (Box) -->
  <link name="base">
    <visual>
      <geometry>
        <box size="0.4 0.03 0.03"/>
      </geometry>
      <material name="base_mat">
        <color rgba="0.8 0.2 0.2 1"/>
      </material>
    </visual>
    <collision>
      <geometry>
        <box size="0.4 0.03 0.03"/>
      </geometry>
    </collision>
    <inertial>
      <mass value="1"/>
      <inertia ixx="0.1" ixy="0.0" ixz="0.0" iyy="0.1" iyz="0.0" izz="0.1"/>
    </inertial>
  </link>

  <!-- Pendulum Arm (Capsule) -->
  <link name="pendulum_arm">
    <visual>
      <geometry>
        <cylinder radius="0.01" length="1.0"/>
      </geometry>
      <origin xyz="0 0 -0.5" rpy="0 0 0"/>
      <material name="arm_mat">
        <color rgba="0.2 0.2 0.8 1"/>
      </material>
    </visual>
    <collision>
      <geometry>
        <cylinder radius="0.01" length="1.0"/>
      </geometry>
      <origin xyz="0 0 -0.5" rpy="0 0 0"/>
    </collision>
    <inertial>
      <mass value="0.5"/>
      <inertia ixx="0.02" ixy="0.0" ixz="0.0" iyy="0.02" iyz="0.0" izz="0.02"/>
    </inertial>
  </link>

  <!-- Sphere at the End of the Pendulum Arm -->
  <link name="pendulum_end">
    <visual>
      <geometry>
        <sphere radius="0.08"/>
      </geometry>
      <material name="end_mat">
        <color rgba="0.1 0.8 0.1 1"/>
      </material>
    </visual>
    <collision>
      <geometry>
        <sphere radius="0.08"/>
      </geometry>
    </collision>
    <inertial>
      <mass value="2.0"/>
      <inertia ixx="0.05" ixy="0.0" ixz="0.0" iyy="0.05" iyz="0.0" izz="0.05"/>
    </inertial>
  </link>

  <!-- Rotational Joint between Base and Pendulum Arm -->
  <joint name="base_to_arm" type="revolute">
    <parent link="base"/>
    <child link="pendulum_arm"/>
    <origin xyz="0 0 0"/>
    <axis xyz="1 0 0"/>
    <limit effort="10" lower="-3.14" upper="3.14" velocity="5"/>
  </joint>

  <!-- Fixed Joint between Pendulum Arm and End Sphere -->
  <joint name="arm_to_end" type="fixed">
    <parent link="pendulum_arm"/>
    <child link="pendulum_end"/>
    <origin xyz="0 0 -1.0"/>
  </joint>

</robot>

